Workbook

Sheet Assumptions
A1: UBER Q2'26F FORECAST ASSUMPTIONS
A2: Assumption | B2: Value | C2: Defense / Source
A3: 1. PLATFORM DRIVERS
A4: MAPCs YoY Growth Rate | B4: 0.175 | C4: Q1'26 actual +17.06%. The earnings call signals continued growth from: Uber One 50M members +50% YoY, 7 new intl markets in Q1'26, insurance-driven US price reductions driving new users.
A5: Q2'25 MAPCs (base — actual) | B5: 180 | C5: Q2'25 actual from press release.
A6: Q2'26F MAPCs (derived) | B6: 212 | C6: Base MAPCs x (1 + growth rate). 180 x 1.175 = 211.5
A8: Monthly Trips per MAPC YoY Growth | B8: 0.03 | C8: Consistent +3% YoY for 4+ consecutive quarters. Balaji Q1'26 call: 'insurance price reductions translating to trip acceleration.
A9: Q2'25 Trips/MAPC (base — actual) | B9: 6.05x | C9: Q2'25 actual: 3,268M / 180M / 3 = 6.05.
A10: Q2'26F Trips/MAPC (derived) | B10: 6.23x | C10: 6.05 x 1.03 = 6.23 monthly trips per MAPC.
A11: Q2'26F Total Trips (derived, M) | B11: 3962 | C11: Derived: MAPCs x Monthly Trips/MAPC x 3 months.
A13: GB per Trip — 12-Qtr Historical Mean | B13: 14.43 | C13: Range-bound $14.10–$14.75 over 12 quarters with no directional trend. Historical mean = $14.43
A14: Q2'26F Total Gross Bookings (derived, $M) | B14: =B13*Consolidated!C17 -> 57054.586 | C14: Derived: Total Trips x GB per Trip.
A16: 2. CONSOLIDATED P&L
A17: Consolidated Take Rate | B17: =Consolidated!H17 -> 0.2433155 | C17: Q2'25 comparable (27.1%). Q1'26 at 24.6% treated as outlier due to contra-revenue reclassification.
A19: EBITDA Margin — ACTIVE SCENARIO (edit to toggle) | B19: 0.0485 | C19: Base case 4.85%. Change to 4.75% (Bear) or 4.96% (Bull).
A20: Q2'26F Adj EBITDA (derived, $M) | B20: =B19*Consolidated!F17 -> 2767.1474 | C20: Total GB x Active EBITDA Margin.
A22: 3. EBITDA MARGIN SCENARIOS
A23: Scenario | B23: EBITDA Margin | C23: Adj EBITDA ($M) | Guidance: $2,700–$2,800M
A24: Bear — 4.75% | B24: 0.0475 | C24: =B24*Consolidated!$F$17 -> 2710.0928
A25: Base — 4.85% (ACTIVE) | B25: 0.0485 | C25: =B25*Consolidated!$F$17 -> 2767.1474
A26: Bull — 4.96% | B26: 0.0496 | C26: =B26*Consolidated!$F$17 -> 2829.9075
A27: Guidance: GB $56.25B–$57.75B | Adj EBITDA $2.70B–$2.80B | Non-GAAP EPS $0.78–$0.82 | Earnings: Aug 5 2026
A29: 4. SEGMENT — GROSS BOOKINGS MIX
A30: Mobility % of Total GB | B30: 0.488 | C30: Mobility mix falling every quarter for past year (from ~51.6% to 49.1%). Q1'26 actual 49.1%.
A31: Delivery % of Total GB | B31: 0.489 | C31: Rising every quarter for past year. Q1'26 at 48.4%. Delivery +23% vs Mobility +20% in Q1'26. Continued growth signals from earnings call: Suburban expansion 'very early innings,' 30% of Mobility users never used Eats.
A32: Freight % of Total GB | B32: 0.023 | C32: Straight-line from Q2'25. Freight returned to growth Q1'26 but one quarter isn't enough to establish a new trend.
A33: Mix check (should = 100.0%) | B33: 1
A35: Mobility GB Q2'26F ($M) | B35: ='Segment - Gross Bookings'!B17 -> 27842.638
A36: Delivery GB Q2'26F ($M) | B36: ='Segment - Gross Bookings'!C17 -> 27899.692
A37: Freight GB Q2'26F ($M) | B37: ='Segment - Gross Bookings'!D17 -> 1312.2555
A39: 5. SEGMENT — REVENUE TAKE RATES
A40: Mobility Take Rate | B40: 0.258 | C40: Q1'25 to Q1'26 = -16%, applied to Q2'25 to account for business model reclassification = 25.80
A41: Delivery Take Rate | B41: =average('Segment - Revenue'!H14:H16) -> 0.193 | C41: 19.3% = avg of last 3 clean quarters.
A42: Freight Take Rate | B42: 1.0015 | C42: 12-quarter average = 100.15%.
A44: Mobility Revenue Q2'26F ($M) | B44: ='Segment - Revenue'!B18 -> 7183.4006
A45: Delivery Revenue Q2'26F ($M) | B45: ='Segment - Revenue'!C18 -> 5384.6406
A46: Freight Revenue Q2'26F ($M) | B46: ='Segment - Revenue'!D18 -> 1314.2239
A47: Total Segment Revenue Q2'26F ($M) | B47: =sum(B44:B46) -> 13882.265
A49: 6. SEGMENT — NON-GAAP OPERATING INCOME
A50: Mobility Op Income Margin (% of Mob GB) | B50: 0.075 | C50: Q4'24 7.1%, Q1'25 7.5%, Q4'25 7.4%, Q1'26 7.7%. Trending up. 7.5% = conservative mid-range.
...

Sheet Consolidated
A1: UBER TECHNOLOGIES - CONSOLIDATED QUARTERLY P&L
A2: Quarter | B2: MAPCs (M) | C2: Trips (M) | D2: Trips / MAPC | E2: GB / Trip ($) | F2: Gross Bookings ($M) | G2: Revenue ($M) | H2: Take Rate | I2: EBITDA Margin | J2: Adj EBITDA ($M) | K2: Non-GAAP OI ($M) | L2: OI / EBITDA | M2: Net Income ($M) | N2: Source
A3: HISTORICAL ACTUALS (Q2 2023 – Q1 2026)
A4: Q2'23 | B4: 137 | C4: 2282 | D4: 5.55 | E4: 14.72 | F4: 33601 | G4: 9230 | H4: 0.275 | I4: 0.027 | J4: 916 | M4: 394 | N4: Q2'24 PR (prior-year column), p.2
A5: Q3'23 | B5: 142 | C5: 2441 | D5: 5.73 | E5: 14.45 | F5: 35281 | G5: 9292 | H5: 0.263 | I5: 0.031 | J5: 1092 | M5: 221 | N5: Q3'24 PR (prior-year column), p.2-3
A6: Q4'23 | B6: 150 | C6: 2601 | D6: 5.78 | E6: 14.45 | F6: 37575 | G6: 9936 | H6: 0.264 | I6: 0.034 | J6: 1283 | M6: 1429 | N6: Q4'24 PR (prior-year column), p.2-3. Non-GAAP OI not disclosed in Q4'24 PR.
A7: Q1'24 | B7: 149 | C7: 2572 | D7: 5.75 | E7: 14.64 | F7: 37651 | G7: 10131 | H7: 0.269 | I7: 0.037 | J7: 1382 | M7: -654 | N7: Q1'25 PR (prior-year column), p.2-3
A8: Q2'24 | B8: 156 | C8: 2765 | D8: 5.91 | E8: 14.45 | F8: 39952 | G8: 10700 | H8: 0.268 | I8: 0.039 | J8: 1570 | M8: 1015 | N8: Q2'24 PR, p.2. NOTE: Take rate impacted by contra-revenue reclassification of S&M costs
A9: Q3'24 | B9: 161 | C9: 2868 | D9: 5.94 | E9: 14.29 | F9: 40973 | G9: 11188 | H9: 0.273 | I9: 0.041 | J9: 1690 | M9: 2612 | N9: Q3'24 PR, p.2-3. NOTE: Mobility take rate impacted -150bps by reclassification
A10: Q4'24 | B10: 171 | C10: 3068 | D10: 5.98 | E10: 14.41 | F10: 44197 | G10: 11959 | H10: 0.271 | I10: 0.042 | J10: 1842 | K10: 1318 | L10: =K10/J10 -> 0.7155266 | M10: 6883 | N10: Q4'24 PR, p.2-3. Non-GAAP OI ($1,318M) from Q4'25 PR comparison. GAAP NI incl $6.4B tax release
A11: Q1'25 | B11: 170 | C11: 3036 | D11: 5.95 | E11: 14.1 | F11: 42818 | G11: 11533 | H11: 0.269 | I11: 0.044 | J11: 1868 | K11: 1326 | L11: =K11/J11 -> 0.70985011 | M11: 1776 | N11: Q1'25 PR, p.2-3. Non-GAAP OI retroactively disclosed in Q1'26 PR
A12: Q2'25 | B12: 180 | C12: 3268 | D12: 6.05 | E12: 14.31 | F12: 46756 | G12: 12651 | H12: 0.271 | I12: 0.045 | J12: 2119 | M12: 1355 | N12: Q2'25 PR, p.2-3
A13: Q3'25 | B13: 189 | C13: 3512 | D13: 6.19 | E13: 14.16 | F13: 49740 | G13: 13467 | H13: 0.271 | I13: 0.045 | J13: 2256 | M13: 6626 | N13: Q3'25 PR, p.2-3. GAAP NI incl $4.9B one-time tax release — not operational
A14: Q4'25 | B14: 202 | C14: 3751 | D14: 6.19 | E14: 14.43 | F14: 54140 | G14: 14366 | H14: 0.265 | I14: 0.046 | J14: 2487 | K14: 1918 | L14: =K14/J14 -> 0.77121029 | M14: 296 | N14: Q4'25 PR, p.2-3. GAAP NI suppressed by $1.6B equity revaluation headwind
A15: Q1'26 | B15: 199 | C15: 3643 | D15: 6.1 | E15: 14.75 | F15: 53720 | G15: 13203 | H15: 0.246 | I15: 0.046 | J15: 2481 | K15: 1883 | L15: =K15/J15 -> 0.75896816 | M15: 263 | N15: Q1'26 PR, p.2-3. NOTE: Mobility rev +5% vs GB +25% — contra-revenue reclassification, not demand weakness
A16: Q2'26F FORECAST (Assumptions tab — change inputs there to update model)
A17: Q2'26F | B17: =B12*(1+Assumptions!B4) -> 211.5 | C17: =B17*D17*3 -> 3953.8868 | D17: =D12*(1+Assumptions!B8) -> 6.2315 | E17: =Assumptions!B13 -> 14.43 | F17: =E17*C17 -> 57054.586 | G17: ='Segment - Revenue'!E18 -> 13882.265 | H17: =G17/F17 -> 0.2433155 | I17: =Assumptions!B19 -> 0.0485 | J17: =Assumptions!B19*F17 -> 2767.1474 | K17: ='Segment - NGOP'!F19 -> 1967.5868 | L17: =K17/J17 -> 0.71105239 | N17: Assumptions tab — see individual assumption defense notes.
A18: NOTES: (1) Q4'24 GAAP NI $6,883M incl $6.4B tax release. (2) Q3'25 GAAP NI $6,626M incl $4.9B tax release. (3) Q1'26 take rate 24.6% = accounting outlier, not structural. (4) Segment Adj EBITDA not disclosed from Q1'26.

Sheet Segment - Gross Bookings
A1: UBER TECHNOLOGIES - SEGMENT GROSS BOOKINGS ($M)
A2: Quarter | B2: Mobility ($M) | C2: Delivery ($M) | D2: Freight ($M) | E2: Total ($M) | F2: Check vs Consol.
A3: HISTORICAL ACTUALS (Q2 2023 – Q1 2026)
A4: Q2'23 | B4: 16728 | C4: 15595 | D4: 1278 | E4: 33601 | F4: —
A5: Q3'23 | B5: 17903 | C5: 16094 | D5: 1284 | E5: 35281 | F5: —
A6: Q4'23 | B6: 19285 | C6: 17011 | D6: 1279 | E6: 37575 | F6: —
A7: Q1'24 | B7: 18670 | C7: 17699 | D7: 1282 | E7: 37651 | F7: —
A8: Q2'24 | B8: 20554 | C8: 18126 | D8: 1272 | E8: 39952 | F8: —
A9: Q3'24 | B9: 21002 | C9: 18663 | D9: 1308 | E9: 40973 | F9: —
A10: Q4'24 | B10: 22798 | C10: 20126 | D10: 1273 | E10: 44197 | F10: —
A11: Q1'25 | B11: 21182 | C11: 20377 | D11: 1259 | E11: 42818 | F11: —
A12: Q2'25 | B12: 23762 | C12: 21734 | D12: 1260 | E12: 46756 | F12: —
A13: Q3'25 | B13: 25111 | C13: 23322 | D13: 1307 | E13: 49740 | F13: —
A14: Q4'25 | B14: 27442 | C14: 25431 | D14: 1267 | E14: 54140 | F14: —
A15: Q1'26 | B15: 26394 | C15: 25992 | D15: 1334 | E15: 53720 | F15: —
A16: Q2'26F FORECAST
A17: Q2'26F | B17: =Consolidated!F17*Assumptions!B30 -> 27842.638 | C17: =Assumptions!B31*Consolidated!F17 -> 27899.692 | D17: =Assumptions!B32*Consolidated!F17 -> 1312.2555 | E17: =sum(B17:D17) -> 57054.586 | F17: =E17-Consolidated!F17 -> 0
A19: HISTORICAL PERCENTAGES (Q2 2023 – Q1 2026)
A20: Q2'23 | B20: =B4/$E4 -> 0.49784233 | C20: =C4/$E4 -> 0.46412309 | D20: =D4/$E4 -> 0.038034582 | E20: =E4 -> 33601 | F20: =1-sum(B20:D20) -> 0
A21: Q3'23 | B21: =B5/$E5 -> 0.50744027 | C21: =C5/$E5 -> 0.45616621 | D21: =D5/$E5 -> 0.036393526 | E21: =E5 -> 35281 | F21: =1-sum(B21:D21) -> 0
A22: Q4'23 | B22: =B6/$E6 -> 0.51324019 | C22: =C6/$E6 -> 0.45272122 | D22: =D6/$E6 -> 0.034038589 | E22: =E6 -> 37575 | F22: =1-sum(B22:D22) -> 0
A23: Q1'24 | B23: =B7/$E7 -> 0.49586996 | C23: =C7/$E7 -> 0.47008048 | D23: =D7/$E7 -> 0.03404956 | E23: =E7 -> 37651 | F23: =1-sum(B23:D23) -> 0
A24: Q2'24 | B24: =B8/$E8 -> 0.51446736 | C24: =C8/$E8 -> 0.45369443 | D24: =D8/$E8 -> 0.031838206 | E24: =E8 -> 39952 | F24: =1-sum(B24:D24) -> 0
A25: Q3'24 | B25: =B9/$E9 -> 0.51258146 | C25: =C9/$E9 -> 0.45549508 | D25: =D9/$E9 -> 0.031923462 | E25: =E9 -> 40973 | F25: =1-sum(B25:D25) -> 0
A26: Q4'24 | B26: =B10/$E10 -> 0.51582687 | C26: =C10/$E10 -> 0.45537027 | D26: =D10/$E10 -> 0.02880286 | E26: =E10 -> 44197 | F26: =1-sum(B26:D26) -> 0
A27: Q1'25 | B27: =B11/$E11 -> 0.49469849 | C27: =C11/$E11 -> 0.47589799 | D27: =D11/$E11 -> 0.029403522 | E27: =E11 -> 42818 | F27: =1-sum(B27:D27) -> 0
A28: Q2'25 | B28: =B12/$E12 -> 0.50821285 | C28: =C12/$E12 -> 0.46483874 | D28: =D12/$E12 -> 0.026948413 | E28: =E12 -> 46756 | F28: =1-sum(B28:D28) -> 0
A29: Q3'25 | B29: =B13/$E13 -> 0.5048452 | C29: =C13/$E13 -> 0.46887817 | D29: =D13/$E13 -> 0.026276639 | E29: =E13 -> 49740 | F29: =1-sum(B29:D29) -> 0
A30: Q4'25 | B30: =B14/$E14 -> 0.50687107 | C30: =C14/$E14 -> 0.46972663 | D30: =D14/$E14 -> 0.02340229 | E30: =E14 -> 54140 | F30: =1-sum(B30:D30) -> 0
A31: Q1'26 | B31: =B15/$E15 -> 0.49132539 | C31: =C15/$E15 -> 0.48384214 | D31: =D15/$E15 -> 0.024832465 | E31: =E15 -> 53720 | F31: =1-sum(B31:D31) -> 0
A32: Q2'26F FORECAST
A33: Q2'26F | B33: =B17/$E17 -> 0.488 | C33: =C17/$E17 -> 0.489 | D33: =D17/$E17 -> 0.023 | E33: =E17 -> 57054.586 | F33: =1-sum(B33:D33) -> 0

Sheet Segment - Revenue
A1: UBER TECHNOLOGIES - SEGMENT REVENUE & TAKE RATES ($M | %)
A2: Revenue Margin = Segment Rev / Segment GB. CAUTION: Q2'24, Q3'24, Q1'26 take rates distorted by contra-revenue reclassification of S&M costs — not organic.
A3: Quarter | B3: Mobility ($M) | C3: Delivery ($M) | D3: Freight ($M) | E3: Total ($M) | F3: Check vs Consol. | G3: Mob Take Rate | H3: Del Take Rate | I3: Frt Take Rate
A4: HISTORICAL ACTUALS (Q2 2023 – Q1 2026)
A5: Q2'23 | B5: 4894 | C5: 3057 | D5: 1279 | E5: 9230 | F5: — | G5: 0.293 | H5: 0.196 | I5: 1.001
A6: Q3'23 | B6: 5071 | C6: 2935 | D6: 1286 | E6: 9292 | F6: — | G6: 0.283 | H6: 0.182 | I6: 1.002
A7: Q4'23 | B7: 5537 | C7: 3119 | D7: 1280 | E7: 9936 | F7: — | G7: 0.287 | H7: 0.183 | I7: 1.001
A8: Q1'24 | B8: 5633 | C8: 3214 | D8: 1284 | E8: 10131 | F8: — | G8: 0.302 | H8: 0.182 | I8: 1.002
A9: Q2'24 | B9: 6134 | C9: 3293 | D9: 1273 | E9: 10700 | F9: — | G9: 0.298 | H9: 0.182 | I9: 1.001
A10: Q3'24 | B10: 6409 | C10: 3470 | D10: 1309 | E10: 11188 | F10: — | G10: 0.305 | H10: 0.186 | I10: 1.001
A11: Q4'24 | B11: 6911 | C11: 3773 | D11: 1275 | E11: 11959 | F11: — | G11: 0.303 | H11: 0.187 | I11: 1.002
A12: Q1'25 | B12: 6496 | C12: 3777 | D12: 1260 | E12: 11533 | F12: — | G12: 0.307 | H12: 0.185 | I12: 1.001
A13: Q2'25 | B13: 7288 | C13: 4102 | D13: 1261 | E13: 12651 | F13: — | G13: 0.307 | H13: 0.189 | I13: 1.001
A14: Q3'25 | B14: 7682 | C14: 4477 | D14: 1308 | E14: 13467 | F14: — | G14: 0.306 | H14: 0.192 | I14: 1.001
A15: Q4'25 | B15: 8204 | C15: 4892 | D15: 1270 | E15: 14366 | F15: — | G15: 0.299 | H15: 0.192 | I15: 1.002
A16: Q1'26 | B16: 6798 | C16: 5068 | D16: 1337 | E16: 13203 | F16: — | G16: 0.258 | H16: 0.195 | I16: 1.002
A17: Q2'26F FORECAST
A18: Q2'26F | B18: =G18*'Segment - Gross Bookings'!B17 -> 7183.4006 | C18: =H18*'Segment - Gross Bookings'!C17 -> 5384.6406 | D18: =I18*'Segment - Gross Bookings'!D17 -> 1314.2239 | E18: =SUM(B18:D18) -> 13882.265 | F18: =E18-Consolidated!G17 -> 0 | G18: =Assumptions!B40 -> 0.258 | H18: =Assumptions!B41 -> 0.193 | I18: =Assumptions!B42 -> 1.0015
A20: HISTORICAL PERCENTAGES (Q2 2023 – Q1 2026)
A21: Q2'23 | B21: =B5/$E5 -> 0.53022752 | C21: =C5/$E5 -> 0.3312026 | D21: =D5/$E5 -> 0.13856988 | E21: =E5 -> 9230 | F21: =1-sum(B21:D21) -> 0
A22: Q3'23 | B22: =B6/$E6 -> 0.54573827 | C22: =C6/$E6 -> 0.31586311 | D22: =D6/$E6 -> 0.13839862 | E22: =E6 -> 9292 | F22: =1-sum(B22:D22) -> 0
A23: Q4'23 | B23: =B7/$E7 -> 0.55726651 | C23: =C7/$E7 -> 0.31390902 | D23: =D7/$E7 -> 0.12882448 | E23: =E7 -> 9936 | F23: =1-sum(B23:D23) -> 0
A24: Q1'24 | B24: =B8/$E8 -> 0.55601619 | C24: =C8/$E8 -> 0.3172441 | D24: =D8/$E8 -> 0.12673971 | E24: =E8 -> 10131 | F24: =1-sum(B24:D24) -> 0
A25: Q2'24 | B25: =B9/$E9 -> 0.57327103 | C25: =C9/$E9 -> 0.30775701 | D25: =D9/$E9 -> 0.11897196 | E25: =E9 -> 10700 | F25: =1-sum(B25:D25) -> 0
A26: Q3'24 | B26: =B10/$E10 -> 0.57284591 | C26: =C10/$E10 -> 0.31015374 | D26: =D10/$E10 -> 0.11700036 | E26: =E10 -> 11188 | F26: =1-sum(B26:D26) -> 0
A27: Q4'24 | B27: =B11/$E11 -> 0.57789113 | C27: =C11/$E11 -> 0.31549461 | D27: =D11/$E11 -> 0.10661427 | E27: =E11 -> 11959 | F27: =1-sum(B27:D27) -> 0
A28: Q1'25 | B28: =B12/$E12 -> 0.56325327 | C28: =C12/$E12 -> 0.32749501 | D28: =D12/$E12 -> 0.10925171 | E28: =E12 -> 11533 | F28: =1-sum(B28:D28) -> 0
A29: Q2'25 | B29: =B13/$E13 -> 0.57608094 | C29: =C13/$E13 -> 0.32424314 | D29: =D13/$E13 -> 0.099675915 | E29: =E13 -> 12651 | F29: =1-sum(B29:D29) -> 0
A30: Q3'25 | B30: =B14/$E14 -> 0.57043142 | C30: =C14/$E14 -> 0.33244227 | D30: =D14/$E14 -> 0.097126309 | E30: =E14 -> 13467 | F30: =1-sum(B30:D30) -> 0
A31: Q4'25 | B31: =B15/$E15 -> 0.57107058 | C31: =C15/$E15 -> 0.34052624 | D31: =D15/$E15 -> 0.088403174 | E31: =E15 -> 14366 | F31: =1-sum(B31:D31) -> 0
A32: Q1'26 | B32: =B16/$E16 -> 0.51488298 | C32: =C16/$E16 -> 0.38385215 | D32: =D16/$E16 -> 0.10126486 | E32: =E16 -> 13203 | F32: =1-sum(B32:D32) -> 0
A33: Q2'26F FORECAST
A34: Q2'26F | B34: =B18/$E18 -> 0.51745162 | C34: =C18/$E18 -> 0.38787911 | D34: =D18/$E18 -> 0.094669267 | E34: =E18 -> 13882.265 | F34: =1-sum(B34:D34) -> 0

Sheet Segment - Adj EBITDA
A1: UBER TECHNOLOGIES - SEGMENT ADJUSTED EBITDA ($M)
A2: CRITICAL: Segment Adj EBITDA not disclosed from Q1'26. Replaced by Segment Non-GAAP Op Income. Do NOT splice these two metrics into one series without noting the break.
A3: Quarter | B3: Mobility ($M) | C3: Delivery ($M) | D3: Freight ($M) | E3: Corp G&A ($M) | F3: Total Adj EBITDA ($M) | G3: Check vs Consol. | H3: Mob Margin | I3: Del Margin
A4: HISTORICAL ACTUALS (Q2 2023 – Q1 2026)
A5: Q2'23 | B5: 1170 | C5: 329 | D5: -14 | E5: -569 | F5: 916 | G5: — | H5: 0.07 | I5: 0.021
A6: Q3'23 | B6: 1287 | C6: 413 | D6: -13 | E6: -595 | F6: 1092 | G6: — | H6: 0.072 | I6: 0.026
A7: Q4'23 | B7: 1446 | C7: 476 | D7: -14 | E7: -625 | F7: 1283 | G7: — | H7: 0.075 | I7: 0.028
A8: Q1'24 | B8: 1479 | C8: 528 | D8: -21 | E8: -604 | F8: 1382 | G8: — | H8: 0.079 | I8: 0.03
A9: Q2'24 | B9: 1567 | C9: 588 | D9: -12 | E9: -573 | F9: 1570 | G9: — | H9: 0.076 | I9: 0.032
A10: Q3'24 | B10: 1682 | C10: 628 | D10: -19 | E10: -601 | F10: 1690 | G10: — | H10: 0.08 | I10: 0.034
A11: Q4'24 | B11: 1769 | C11: 727 | D11: -22 | E11: -632 | F11: 1842 | G11: — | H11: 0.078 | I11: 0.036
A12: Q1'25 | B12: 1753 | C12: 763 | D12: -7 | E12: -641 | F12: 1868 | G12: — | H12: 0.083 | I12: 0.037
A13: Q2'25 | B13: 1905 | C13: 873 | D13: -6 | E13: -653 | F13: 2119 | G13: — | H13: 0.08 | I13: 0.04
A14: Q3'25 | B14: 2038 | C14: 921 | D14: -20 | E14: -683 | F14: 2256 | G14: — | H14: 0.081 | I14: 0.039
A15: Q4'25 | B15: 2203 | C15: 1015 | D15: 0 | E15: -731 | F15: 2487 | G15: — | H15: 0.08 | I15: 0.04
A16: Q1'26 | B16: N/D | C16: N/D | D16: N/D | E16: N/D | F16: N/D | G16: Not disclosed from Q1'26 — see Op Income tab
A17: Q2'26F FORECAST
A18: Q2'26F | B18: N/D | C18: N/D | D18: N/D | E18: N/D | F18: N/D | G18: Not disclosed from Q1'26 onward

Sheet Segment - NGOP
A1: UBER TECHNOLOGIES - SEGMENT NON-GAAP OPERATING INCOME ($M)
A2: Replaces Segment Adj EBITDA from Q1'26. Q4'24 and Q1'25 retroactively disclosed in Q1'26 PR. Prior quarters = N/A (not reported).
A3: NEW PRIMARY METRIC from Q1'26 — replaces Segment Adjusted EBITDA. See Notes tab.
A4: Quarter | B4: Mobility ($M) | C4: Delivery ($M) | D4: Freight ($M) | E4: Corp G&A ($M) | F4: Total Non-GAAP OI ($M) | G4: Check vs Consol. | H4: Mob Margin | I4: Del Margin | J4: Frt Margin | K4: Corp G&A %
A5: HISTORICAL (prior to Q4'24 = N/A — not disclosed)
A6: Q2'23 | B6: N/A | C6: N/A | D6: N/A | E6: N/A | F6: N/A | G6: N/A
A7: Q3'23 | B7: N/A | C7: N/A | D7: N/A | E7: N/A | F7: N/A | G7: N/A
A8: Q4'23 | B8: N/A | C8: N/A | D8: N/A | E8: N/A | F8: N/A | G8: N/A
A9: Q1'24 | B9: N/A | C9: N/A | D9: N/A | E9: N/A | F9: N/A | G9: N/A
A10: Q2'24 | B10: N/A | C10: N/A | D10: N/A | E10: N/A | F10: N/A | G10: N/A
A11: Q3'24 | B11: N/A | C11: N/A | D11: N/A | E11: N/A | F11: N/A | G11: N/A
A12: Q4'24 | B12: 1608 | C12: 639 | D12: -41 | E12: -888 | F12: 1318 | G12: — | H12: 0.071 | I12: 0.032 | J12: -0.032 | K12: -0.02
A13: Q1'25 | B13: 1587 | C13: 671 | D13: -25 | E13: -907 | F13: 1326 | G13: — | H13: 0.075 | I13: 0.033 | J13: -0.02 | K13: -0.021
A14: Q2'25 | B14: N/A | C14: N/A | D14: N/A | E14: N/A | F14: N/A | G14: N/A
A15: Q3'25 | B15: N/A | C15: N/A | D15: N/A | E15: N/A | F15: N/A | G15: N/A
A16: Q4'25 | B16: 2027 | C16: 905 | D16: -18 | E16: -996 | F16: 1918 | G16: — | H16: 0.074 | I16: 0.036 | J16: -0.014 | K16: -0.018
A17: Q1'26 | B17: 2029 | C17: 961 | D17: -30 | E17: -1077 | F17: 1883 | G17: — | H17: 0.077 | I17: 0.037 | J17: -0.022 | K17: -0.02
A18: Q2'26F FORECAST
A19: Q2'26F | B19: =H19*'Segment - Gross Bookings'!B17 -> 2088.1978 | C19: =I19*'Segment - Gross Bookings'!C17 -> 1004.3889 | D19: =Assumptions!B52 -> -28 | E19: =Assumptions!B53 -> -1097 | F19: =sum(B19:E19) -> 1967.5868 | G19: =F19-Consolidated!K17 -> 0 | H19: =Assumptions!B50 -> 0.075 | I19: =Assumptions!B51 -> 0.036

Sheet Notes
A1: UBER TECHNOLOGIES - MODEL NOTES
A2: CRITICAL: METRIC CHANGE AT Q1'26
B3: Starting Q1'26, Uber no longer reports Segment Adjusted EBITDA. Replaced by Non-GAAP Operating Income at segment level.
A5: CRITICAL: TAKE RATE NOISE
B6: Q2'24, Q3'24, and Q1'26 take rates are distorted by disclosed 'business model changes' that reclassify certain S&M costs as contra-revenue.
A9: KNOWN DISCLOSURE GAPS
A10: Seg Trips/MAPCs | B10: NOT disclosed at segment level. Only consolidated Trips/MAPCs available.
A11: Non-GAAP OI history | B11: Only available for Q4'24, Q1'25, Q4'25, Q1'26. Q4'24 and Q1'25 disclosed in Q1'26 PR.
A13: Q2'26F KEY ASSUMPTIONS
A14: MAPCs | B14: 17.5% YoY growth. In the earnings call, we see Uber One hit 50M members +50% YoY, 7 new intl markets, insurance-driven US user acquisition. All signs point to bullish outlook for MAPC growth.
A15: Trips/MAPC | B15: 3% YoY → 6.23/month. Consistent 4-quarter trend, in earnings call: Balaji confident on repeat trips for MAPC's continuing through 2026.
A16: GB/Trip | B16: $14.43 (12-quarter historical mean)
A17: Take Rate | B17: 27.1% (Q2'25 straight-line). Q1'26 at 24.6% treated as outlier due to reclassification of S&M costs to contra-revenue.
A18: EBITDA Margin | B18: 4.85% base (+0.43pp additive YoY trend). Insurance savings tailwind via Q1'26 call.
A19: Segment Mix | B19: Mobility 48.8% / Delivery 48.9% / Freight 2.3%. Delivery taking share steadily for past year, so I expect it to finally pass mobility in GB share.
